# Generated by Django 3.2.9 on 2021-11-14 05:50

from django.conf import settings
from django.db import migrations, models
import django.db.models.deletion


class Migration(migrations.Migration):

    dependencies = [
        migrations.swappable_dependency(settings.AUTH_USER_MODEL),
        ('task_manager', '0005_column_is_text'),
    ]

    operations = [
        migrations.CreateModel(
            name='AsyncErrorMessage',
            fields=[
                ('id', models.BigAutoField(auto_created=True, primary_key=True, serialize=False, verbose_name='ID')),
                ('happened_time', models.DateTimeField(auto_now_add=True, verbose_name='发生时间')),
                ('current_step', models.IntegerField(default=3, verbose_name='创建步骤')),
                ('error_message', models.TextField(blank=True)),
                ('task', models.ForeignKey(on_delete=django.db.models.deletion.CASCADE, to='task_manager.task', verbose_name='任务')),
                ('user', models.ForeignKey(on_delete=django.db.models.deletion.CASCADE, to=settings.AUTH_USER_MODEL, verbose_name='用户')),
            ],
            options={
                'verbose_name': '异步错误',
                'verbose_name_plural': '异步错误',
            },
        ),
    ]
